Workbook

Sheet Overall
A1: Club Name | B1: Recurring | C1: Non-Recurring | D1: Total | E1: LAST YEAR'S TOTAL | F1: Difference | G1: %age change | I1: Table of Content
A2: (Annexure 1) Coding Club | B2: ='Coding Club'!B3 -> 165500 | C2: ='Coding Club'!B4 -> 0 | D2: =B2+C2 -> 165500 | E2: 266740 | F2: =MINUS(D2,E2) -> #NAME? | G2: =DIVIDE(F2,E2)*100 -> #NAME? | I2: Annexure No. | J2: Details
A3: (Annexure 2) SDS Club | B3: ='Space Data Science Club'!B2 -> 66200 | C3: ='Space Data Science Club'!B3 -> 130304 | D3: =B3+C3 -> 196504 | E3: 169760 | F3: =MINUS(D3,E3) -> #NAME? | G3: =DIVIDE(F3,E3)*100 -> #NAME? | I3: Annexure-1 | J3: Coding Club
A4: (Annexure 3) AI Club | B4: ='AI Club'!B3 -> 57000 | C4: ='AI Club'!B4 -> 0 | D4: =B4+C4 -> 57000 | E4: 257600 | F4: =MINUS(D4,E4) -> #NAME? | G4: =DIVIDE(F4,E4)*100 -> #NAME? | I4: Annexure-2 | J4: Space Data Science Club
A5: (Annexure 4) Robotics Club | B5: ='Robotics Club'!B3 -> 126643 | C5: ='Robotics Club'!B4 -> 265650 | D5: =B5+C5 -> 392293 | E5: 265296 | F5: =MINUS(D5,E5) -> #NAME? | G5: =DIVIDE(F5,E5)*100 -> #NAME? | I5: Annexure-3 | J5: AI Club
A6: (Annexure 5) Insolvent | B6: ='Finance Club'!B3 -> 55140 | C6: ='Finance Club'!B4 -> 0 | D6: =B6+C6 -> 55140 | E6: 426300 | F6: =MINUS(D6,E6) -> #NAME? | G6: =DIVIDE(F6,E6)*100 -> #NAME? | I6: Annexure-4 | J6: Robotics Club
A7: (Annexure 6) InGene | B7: ='Ingene Motorsport'!B3 -> 53550 | C7: ='Ingene Motorsport'!B4 -> 22000 | D7: =B7+C7 -> 75550 | E7: 363000 | F7: =MINUS(D7,E7) -> #NAME? | G7: =DIVIDE(F7,E7)*100 -> #NAME? | I7: Annexure-5 | J7: Insolvent Finance Club
A8: (Annexure 7) Design Club | B8: ='Abhikalpa Design Club'!B3 -> 44000 | C8: ='Abhikalpa Design Club'!B4 -> 43826 | D8: =B8+C8 -> 87826 | E8: 124400 | F8: =MINUS(D8,E8) -> #NAME? | G8: =DIVIDE(F8,E8)*100 -> #NAME? | I8: Annexure-6 | J8: InGene Motorsports Club
A9: (Annexure 8) Astronomy Club | B9: ='Astronomy Club'!B3 -> 45000 | C9: ='Astronomy Club'!B4 -> 61077 | D9: =B9+C9 -> 106077 | E9: 161561 | F9: =MINUS(D9,E9) -> #NAME? | G9: =DIVIDE(F9,E9)*100 -> #NAME? | I9: Annexure-7 | J9: Design Club
A10: (Annexure 9) Electronics Club | B10: ='Electronics Club'!B3 -> 111692 | C10: ='Electronics Club'!B4 -> #NAME? | D10: =B10+C10 -> #NAME? | E10: 631306 | F10: =MINUS(D10,E10) -> #NAME? | G10: =DIVIDE(F10,E10)*100 -> #NAME? | I10: Annexure-8 | J10: Astronomy Club
A11: (Annexure 10) Summer of Innovation (SoI 2026) | B11: ='SoI26'!F21 -> 100000 | C11: 0 | D11: =B11+C11 -> 100000 | E11: NA | I11: Annexure-9 | J11: Electronics Club
A12: (Annexure 11) Inter IIT Tech Meet 15.0 | B12: =InterIIT!D11 -> 1979850 | C12: 0 | D12: =B12+C12 -> 1979850 | E12: 1436540 | F12: =MINUS(D12,E12) -> #NAME? | G12: =DIVIDE(F12,E12)*100 -> #NAME? | I12: Annexure-10 | J12: Summer of Innovation (SoI 2026)
A13: (Annexure 12) PARSEC 7.0 | B13: =PARSEC!D12 -> 2000000 | C13: 0 | D13: =B13+C13 -> 2000000 | E13: 1200000 | F13: =MINUS(D13,E13) -> #NAME? | G13: =DIVIDE(F13,E13)*100 -> #NAME? | I13: Annexure-11 | J13: Inter IIT Tech Meet 14.0
A14: (Annexure 13) Club Merch | B14: =ClubMerch!E17 -> 304500 | C14: 0 | D14: =B14+C14 -> 304500 | E14: NA | I14: Annexure-12 | J14: PARSEC 7.0
A15: Total | D15: =SUM(D2:D14) -> #NAME? | E15: =SUM(E2:E13) -> 5302503 | F15: =MINUS(D15,E15) -> #NAME? | G15: =DIVIDE(F15,E15)*100 -> #NAME? | I15: Annexure-13 | J15: ClubMerch

Sheet Coding Club
A1: Overview
A2: Type | B2: Amount
A3: Recurring | B3: =SUM(E55,G157) -> 165500
A4: Non-Recurring | B4: =E59 -> 0
A5: Total | B5: =SUM(B3:B4) -> 165500
A7: Projects
A9: Web Wing:
A11: Project-i) | B11: IRO(International Relations) website.
A12: Project Lead: | B12: Lataksh Sariya
A13: Project Duration: | B13: 1 month
A15: Project-ii) | B15: RnD website
A16: Project Lead: | B16: Srinivas
A17: Project Duration: | B17: Completed (Deployment Remaining)
A19: Project-iii) | B19: student welfare website
A20: Project Lead: | B20: Varshith Kamatham
A21: Project Duration: | B21: Under Continued Maintainence
A23: Project-iv) | B23: SAM Portal
A24: Project Lead: | B24: Maneesha
A25: Project Duration: | B25: Under Continued Maintainence
... A29: Project Duration: | B29: 1 month
A31: Systems Wing:
A33: Project-i) | B33: Design and Verification of processor:
A34: Project Lead: | B34: Srinivas and Smaran
A35: Project Duration: | B35: n/a
A37: Project-ii) | B37: Embedded streaming interpreter:
A38: Project Lead: | B38: Gourav
A39: Project Duration: | B39: Entire Semester
A41: Project-iii) | B41: Man in the middle:
A42: Project Lead: | B42: Tapash
A43: Project Duration: | B43: Entire Semester
A45: Project-iv) | B45: Distributed GPUs:
A46: Project Lead: | B46: Anshuman Rahul
A47: Project Duration: | B47: Entire Semester
A49: Recurring Budget
A50: Sr. No. | B50: Description of Item | C50: Cost (per unit) | D50: Quantity | E50: Amount | F50: Reference Link
A51: 1 | B51: Claude Pro Subscription | C51: 23000 | D51: 1 | E51: 23000 | F51: Link
A52: 2 | B52: Game Assets | E52: 5000
A53: 3 | B53: Honorarium for SW Website & Maintainence | C53: 5000 | D53: 2 | E53: =C53*D53 -> 10000
A54: 4 | B54: Website & Maintainence of SmartMess, SAM Portal, etc. | C54: 3000 | D54: 5 | E54: =C54*D54 -> 15000
B55: TOTAL | E55: =SUM(E51:E53) -> 38000
...

Sheet Space Data Science Club
A1: Type | B1: Amount
A2: Recurring | B2: =E19+E86+E94+C99 -> 66200
A3: Non-Recurring | B3: =E76 -> 130304
A4: Total | B4: =SUM(B2:B3) -> 196504
A6: Projects
A7: Project-CubeSat
A8: Project Lead: Affan P
A9: Project Duration: Aug 2026 to Jan 2027
A11: Project-Self-Balancing Cube
A12: Project Lead: Balamurali V B
A13: Project Duration: Aug 2026 to Jan 2027
A15: Recurring Budget
A16: Sr. No. | B16: Description of Item | C16: Cost (per unit) | D16: Quantity | E16: Amount | F16: Reference Link | G16: Justification
A17: 1 | B17: PETG Filament | C17: 800 | D17: 2 | E17: =C17*D17 -> 1600 | F17: Link | G17: Filament for 3D printing
A18: 2 | B18: PLA Filament | C18: 800 | D18: 2 | E18: =C18*D18 -> 1600 | F18: Link | G18: Filament for 3D printing
D19: Total | E19: =SUM(E17:E18) -> 3200
A21: Non-Recurring Budget
A22: Sr. No. | B22: Description of Item | C22: Cost (per unit) | D22: Quantity | E22: Amount | F22: Reference Link | G22: Justification
A23: 1 | B23: 2204 260KV Brushless Gimbal Motor | C23: 1200 | D23: 4 | E23: =C23*D23 -> 4800 | F23: Link | G23: Parts of research and development of CubeSat -ADCS (1-7)
A24: 2 | B24: Magnetic encoder sensor module AS5600 | C24: 200 | D24: 6 | E24: =C24*D24 -> 1200 | F24: Link
A25: 3 | B25: Orange 11.1V 600mAh 25C 3S Lithium Polymer Battery Pack | C25: 1300 | D25: 1 | E25: =C25*D25 -> 1300 | F25: Link
A26: 4 | B26: LM2596S-5.0-XBLW-Step-down type Fixed 5V TO-263-5L DC-DC Converters ROHS | C26: 100 | D26: 3 | E26: =C26*D26 -> 300 | F26: Link
A27: 5 | B27: ESP32 S3 Devkit (ESP32 S3 WROOM 1 N16R8 | 16MB Flash + 8MB PSRAM) | C27: 1000 | D27: 2 | E27: =C27*D27 -> 2000 | F27: Link
A28: 6 | B28: SimpleFOCmini Brushless DC Motor Driver Board | C28: 800 | D28: 4 | E28: =C28*D28 -> 3200 | F28: Link
A29: 7 | B29: CJMCU TCA9548A I2C 8 Channel Multiple Extensions Development Board | C29: 100 | D29: 2 | E29: =C29*D29 -> 200 | F29: Link
A30: 8 | B30: Ebyte E32-433T20D-V8 UART/SX1278 410-441Mhz Wireless LoRa Module | C30: 900 | D30: 3 | E30: =C30*D30 -> 2700 | F30: Link | G30: Parts for research and development of Sensors and Communications.(8-16)
A31: 9 | B31: VEML6075 UV Sensor Module | C31: 820 | D31: 3 | E31: =C31*D31 -> 2460 | F31: Link
A32: 10 | B32: NEO-M8N GPS Module with Ceramic Active Antenna | C32: 2550 | D32: 2 | E32: =C32*D32 -> 5100 | F32: Link
A33: 11 | B33: 18650 Li-Ion Cell 3.7V 2500mAh (INR) | C33: 526 | D33: 10 | E33: =C33*D33 -> 5260 | F33: Link
A34: 12 | B34: 2S 20A 18650 BMS Protection Board (HX-2S-D20) | C34: 130 | D34: 8 | E34: =C34*D34 -> 1040 | F34: Link
A35: 13 | B35: WeAct STM32F103C8T6 Bluepill Plus Dev Board | C35: 350 | D35: 2 | E35: =C35*D35 -> 700 | F35: Link
A36: 14 | B36: ST-Link V2 Programmer (STM8/STM32 SWD) | C36: 395 | D36: 2 | E36: =C36*D36 -> 790 | F36: Link
A37: 15 | B37: Arduino Nano | C37: 300 | D37: 2 | E37: =C37*D37 -> 600 | F37: Link
A38: 16 | B38: Buck converter | C38: 75 | D38: 2 | E38: =C38*D38 -> 150 | F38: Link
A39: 17 | B39: Double-aluminized polyimide / Kapton films | E39: 19000 | G39: Aerospace grade tape to act as heat sink
A40: 18 | B40: TPS2595 EVM | C40: 8250 | D40: 1 | E40: 8250 | F40: Link | G40: Parts for Research and Development of CubeSat EPS(18-53)
A41: 19 | B41: MSP-EXP430FR5969 LaunchPad | C41: 1760 | D41: 2 | E41: 3520 | F41: Link
A42: 20 | B42: TPS3890 EVM/breakout | C42: 2200 | D42: 1 | E42: 2200 | F42: Link
A43: 21 | B43: TPL5010 EVM/breakout // direct prototype | C43: 3190 | D43: 1 | E43: 3190 | F43: Link
A44: 22 | B44: BQ24103A EVM | C44: 5390 | D44: 1 | E44: 5390 | F44: Link
...

Sheet AI Club
A1: Overview
A2: Type | B2: Amount
A3: Recurring | B3: =SUM(E26,E39,E47,E65,E59) -> 57000
A4: Non-Recurring
A5: Total | B5: =SUM(B3:B4) -> 57000
A7: Projects
A8: Project-i) | B8: Speech Emotion Recognition (SER)
A9: Project Lead: | B9: Dhanush H N (cs23bt010) & Priyanshu (is23bm007)
A10: Project Duration: | B10: 6-7 Months
A12: Project-ii) | B12: Deepfake Detection
A13: Project Lead: | B13: Mallireddy Rupesh (cs23bt025)
A14: Project Duration: | B14: 7 months
A16: Project-iii) | B16: sEMG-Based Hand Gesture Recognition
A17: Project Lead: | B17: Aayushi Singh (is24bm037)
A18: Project Duration: | B18: 7 months
A20: Project-iv&v) | B20: Gesture Controlled Game & Company Analysis Chatbot
A23: Recurring Budget
A24: Sr. No. | B24: Description of Item | C24: Cost (per unit) | D24: Quantity | E24: Amount | F24: Reference Link
A25: 1 | B25: OpenAI API (GPT models) | C25: 10000 | D25: 1 | E25: =C25*D25 -> 10000 | F25: https://openai.com/api/pricing/
B26: Total | E26: =SUM(E25) -> 10000
A28: Non-Recurring Budget
A29: Sr. No. | B29: Description of Item | C29: Cost (per unit) | D29: Quantity | E29: Amount | F29: Reference Link
A31: Events
A34: Event Name: | B34: Smart India Hackathon (Internal Hackathon)
A35: Tentative Date and Duration: <start date and end date> | B35: August/ September 2026 24h duration
A36: Prize Pool:
A37: Sr. No. | B37: Description of Item | C37: Cost (per unit) | D37: Quantity | E37: Amount | F37: Reference Link
A38: 1 | B38: Merchandise for Top 5 Teams (6 per team) | C38: 400 | D38: 30 | E38: 12000
B39: Total | E39: =SUM(E38) -> 12000
A41: Event Name: | B41: Hackastra (AI Hackathon)
A42: Tentative Date and Duration: <start date and end date> | B42: 06/03/2027-07/03/2027 24hr Duration
A43: Prize Pool: 15000
A44: Sr. No. | B44: Description of Item | C44: Cost (per unit) | D44: Quantity | E44: Amount | F44: Reference Link
A45: 1 | B45: Catering | C45: 40 | D45: 100 | E45: 4000 | G45: 100 each
A46: 2 | B46: Prize Pool (Goodies and Vouchers) | C46: 15000 | D46: 1 | E46: 15000 | F46: - 1st: 7000 - 2nd: 5000 - 3rd: 3000
B47: Total | E47: =SUM(E45:E46) -> 19000
A49: Event Name: | B49: Machine Learning Workshop
A50: Tentative Date and Duration: <start date and end date> | B50: September 2026 2hr Duration
A52: Event Name: | B52: Artificial Intelligence workshop
A53: Tentative Date and Duration: <start date and end date> | B53: feb/march 2027 2hr Duration
...

Sheet Robotics Club
A1: Overview
A2: Type | B2: Amount
A3: Recurring | B3: =E78 -> 126643
A4: Non-Recurring | B4: =E183 -> 265650
A5: Total | B5: =SUM(B3:B4) -> 392293
A7: Projects
A8: Project 1 | B8: Drone Project | C8: Project focuses on getting a lightweight(~2kg) drone operational with minimal error for given commands On completion of previous milestone, we plan to add autonomous control through mapping, path planning, etc which will be useful for a wide range of applications Target competitions : IRDC, IRoCu
A9: Project Leads | B9: Balamurli V, Naitik Goyal
A10: Duration | B10: 2+ Semesters
A12: Project 2 | B12: Biped Project | C12: Focuses on building and training a biped robot using Reinforcement Learning to walk. Start training in simulation, add more realistic constraints to bridge Sim to Real gap Once we receive parts, build it component by component, with thorough testing of each
A13: Project Leads | B13: Shrikant Sonawane, Tushar Hegde
A14: Duration | B14: 2+ Semesters
A16: Project 3 | B16: Rover Project | C16: Project focuses on building a functioning rover with mapping, path planning, stable communication systems, camera feedback, etc (Project is mainly meant for competition entry as well as learning robotics while building it.) Target competition : IRC/IRDC, look at overseas competitions if successful enough
A17: Project Leads | B17: Soumya Basuli, Anushaa B
A18: Duration | B18: 3+ Semesters
A20: Project 4 | B20: Robotic Arm Project | C20: A stand alone project as well as a supplement to the rover, its first main milestone is getting an arm designed, built and functional so that we can control it with commands. After the previous milestone, we can work on - Autonomous control, ML algorithms for it, Pair it with computer vision, etc
A21: Project Leads | B21: Simarjeet Singh, Tushar Hegde | C21: NOTE : Parts not included in budget, approval required once rover reaches a significant milestone
A22: Duration | B22: Up to 2 Semesters
A24: Recurring Budget
A25: Sr. No. | B25: Description of Item | C25: Cost (per unit) | D25: Quantity | E25: Amount | F25: Reference Link
A26: 1 | B26: Assorted Resistors | C26: 3 | D26: 50 | E26: =C26*D26 -> 150 | F26: robocraze
A27: 2 | B27: Assorted Capacitors | C27: 2 | D27: 100 | E27: =C27*D27 -> 200
A28: 3 | B28: Pushbuttons Pack | C28: 3 | D28: 160 | E28: =C28*D28 -> 480 | F28: robocraze
A29: 4 | B29: Toggle Swtiches Pack 3 Amps | C29: 5 | D29: 70 | E29: =C29*D29 -> 350 | F29: robocraze
A30: 5 | B30: Rocker Switch 16 Amps | C30: 10 | D30: 60 | E30: =C30*D30 -> 600 | F30: robocraze
A31: 6 | B31: Cable Sleeves Pack | C31: 2 | D31: 300 | E31: =C31*D31 -> 600
A32: 7 | B32: Berg Strips/ Pinheaders Male | C32: 20 | D32: 10 | E32: =C32*D32 -> 200 | F32: robocraze
A33: 8 | B33: Berg Strips/ Pinheaders Female | C33: 20 | D33: 10 | E33: =C33*D33 -> 200 | F33: robocraze
A34: 9 | B34: XT60 Connector Pair | C34: 10 | D34: 30 | E34: =C34*D34 -> 300 | F34: robocraze
A35: 10 | B35: Wires Assorted Gauges | C35: 10 | D35: 50 | E35: =C35*D35 -> 500
A36: 11 | B36: Potentiometers 10K Pack | C36: 3 | D36: 150 | E36: =C36*D36 -> 450 | F36: robocraze
A37: 12 | B37: AMS1117 3.3V Regulator | C37: 20 | D37: 20 | E37: =C37*D37 -> 400 | F37: robocraze
A38: 13 | B38: L7805 5V Regulator | C38: 20 | D38: 20 | E38: =C38*D38 -> 400 | F38: robocraze
A39: 14 | B39: Soldering Wire | C39: 5 | D39: 130 | E39: =C39*D39 -> 650 | F39: robocraze
A40: 15 | B40: Solering Iron Sponge | C40: 5 | D40: 20 | E40: =D40*C40 -> 100 | F40: robocraze
A41: 16 | B41: Soldering Flux Paste | C41: 3 | D41: 30 | E41: =D41*C41 -> 90 | F41: robocraze
A42: 17 | B42: JSTConnectors | C42: 4 | D42: 200 | E42: =C42*D42 -> 800 | F42: robocraze, robocraze
A43: 18 | B43: Fuse | C43: 10 | D43: 100 | E43: =C43*D43 -> 1000 | F43: robocraze
A44: 19 | B44: M3 Screws set | C44: 2 | D44: 400 | E44: =D44*C44 -> 800 | F44: robu
A45: 20 | B45: M4 Screws + Nut Set | C45: 4 | D45: 115 | E45: =D45*C45 -> 460 | F45: robu
...

Sheet Finance Club
A1: Overview
A2: Type | B2: Amount
A3: Recurring | B3: =E27+B60 -> 55140
A4: Non-Recurring
A5: Total | B5: =SUM(B3:B4) -> 55140
A8: Projects Planned for 2026-2027
A9: Name | B9: Timeline
A10: 1) Crypto Trading bot | B10: 1 semester
A11: 2) Case Studies of World Economic situations | B11: Goes on for the whole year
A12: 3) Developing Quantitative finance trading algorithms | B12: Goes on for the whole year
A13: 4) Framework to test Trading Algorithms | B13: 1 semester
A14: 5) Paper Trading App | B14: 1 semester
A17: Non-Recurring Budget
A18: Sr. No. | B18: Description of Item | C18: Cost (per unit) | D18: Quantity | E18: Amount | F18: Reference Link
D19: Total
A21: Recurring Budget
A22: Subscriptions
A23: Sr. No. | B23: Description of Item | C23: Cost (per unit) | D23: Quantity | E23: Amount | F23: Reference Link
A24: 1) | B24: Zerodha Kite connect Api | C24: 500 per month | D24: 12 months | E24: 6000 | F24: https://zerodha.com/products/api/
A25: 2) | B25: Trading view Plus Subscription (Annual Billing) | C25: 2095 per month | D25: 12 months | E25: 25140 | F25: https://in.tradingview.com/pricing/
A26: 3) | B26: The Captable | C26: 4000 per year | D26: 1 | E26: 4000 | F26: https://the-captable.com/subscription/
D27: Total | E27: =SUM(E24:E26) -> 35140
A29: Events
A31: Workshops
B32: Event Name | C32: Event Date
A33: A) | B33: Intro to Finance Workshop | C33: 30th August 2026
A34: B) | B34: Quantitative Finance Research Workshop | C34: 24th October 2026
A35: D) | B35: FinTech Workshop | C35: 13th March 2027
A37: Competitions | B37: (All prize money in terms of vouchers)
B38: Description | C38: Amount: | D38: No. | E38: Budget | F38: Budget Breakdown:
A39: Event Name | B39: Algo Trading Competition
A40: Event Timeline | B40: 1/2/2027 to 7/2/2027
A41: Prize money | B41: Prize money in kind | C41: 5000 | D41: 1 | E41: =C41*D41 -> 5000 | F41: 2500+1500+1000
D42: Total | E42: 5000
A44: Event Name | B44: Paper Trading Competition
A45: Event Timeline | B45: 1/11/2026 to 7/11/2026
A46: Prize money | B46: Prize money in kind | C46: 5000 | D46: 1 | E46: =C46*D46 -> 5000 | F46: 2500+1500+1000
D47: Total | E47: 5000
A49: Event Name | B49: Case Studies Competition
A50: Event Timeline | B50: 5/9/2026 to 12/9/2026
...

Sheet Ingene Motorsport
A1: Overview
A2: Type | B2: Amount
A3: Recurring | B3: =SUM(E30,E50) -> 53550
A4: Non-Recurring | B4: =SUM(E37) -> 22000
A5: Total | B5: =SUM(B3:B4) -> 75550
A7: Projects
A8: Project-i) Formula Bharat
A9: Project Lead: Nageswar
A10: Project Duration: 1 year
A12: Project-ii) VTOL Drone
A13: Project Lead: Aadhi Shankar
A14: Project Duration: 1 year
A16: Recurring Budget
A17: Sr. No. | B17: Description of Item | C17: Cost (per unit) | D17: Quantity | E17: Amount | F17: Reference Link
A18: 1 | B18: Li-Po Battery | C18: 3900 | D18: 2 | E18: =C18*D18 -> 7800 | F18: Link
A19: 2 | B19: 1400Kv Motor | C19: 410 | D19: 4 | E19: =C19*D19 -> 1640 | F19: Link
A20: 3 | B20: 1100Kv Motor | C20: 1500 | D20: 1 | E20: =C20*D20 -> 1500 | F20: Link
A21: 4 | B21: Electronic Speed Controller - 40A | C21: 2700 | D21: 5 | E21: =C21*D21 -> 13500 | F21: Link
A22: 5 | B22: Electronic Speed Controller - 60A | C22: 3100 | D22: 1 | E22: =C22*D22 -> 3100 | F22: Link
A23: 6 | B23: Power Module | C23: 590 | D23: 1 | E23: =C23*D23 -> 590 | F23: Link
A24: 7 | B24: Power Distribution Board | C24: 350 | D24: 2 | E24: =C24*D24 -> 700 | F24: Link
A25: 8 | B25: Shock Absorber | C25: 180 | D25: 1 | E25: =C25*D25 -> 180 | F25: Link
A26: 9 | B26: Air Speed Sensor | C26: 3900 | D26: 1 | E26: =C26*D26 -> 3900 | F26: Link
A27: 10 | B27: Carbon Fiber Tubes | C27: 1220 | D27: 2 | E27: =C27*D27 -> 2440 | F27: Link
A28: 11 | B28: PLA+ 3D printer filament | C28: 800 | D28: 3 | E28: =C28*D28 -> 2400 | F28: Link
A29: 12 | B29: PETG 3D printer filament | C29: 800 | D29: 1 | E29: =C29*D29 -> 800 | F29: Link
D30: Total | E30: =SUM(E18:E29) -> 38550
A32: Non-Recurring Budget
A33: Sr. No. | B33: Description of Item | C33: Cost (per unit) | D33: Quantity | E33: Amount | F33: Reference Link
A34: 5 | B34: CNC Vacuum cleaner | C34: 9000 | D34: 1 | E34: =C34*D34 -> 9000 | F34: Link
A35: 6 | B35: Pixhawk Flight Controller | C35: 6500 | D35: 1 | E35: =C35*D35 -> 6500 | F35: Link
A36: 7 | B36: Flysky Fs-I6X Transmitter + Fs-Ia10B Receiver (10Ch) | C36: 6500 | D36: 1 | E36: =C36*D36 -> 6500 | F36: Link
D37: Total | E37: =SUM(E34:E36) -> 22000
A39: Events
A41: Event Name: CAD Workshop with Abhikalpa
A42: Tentative Date and Duration: 22nd-23rd August
A43: Prize Pool: None
A45: Event Name: Model Mania (3D Modelling Competition) with Design
A46: Tentative Date and Duration: Even Sem
A47: Prize pool: 15000
...

Sheet Abhikalpa Design Club
A1: Overview
A2: Type | B2: Amount
A3: Recurring | B3: =SUM(E38,E94,E107) -> 44000
A4: Non-Recurring | B4: =SUM(E43,E84) -> 43826
A5: Total | B5: =SUM(B3:B4) -> 87826
A7: Projects
A9: Project 1 : | B9: Folding Geometry
A10: Project Lead: | B10: Rajat
A11: Project Duration: | B11: Entire Sem
A12: Project Wing: | B12: Product Design wing
A14: Project 2 : | B14: 2-in-1 Speaker cum Headset
A15: Project Lead: | B15: Swayam
A16: Project Duration: | B16: Throughout the year
A17: Project Wing: | B17: Product Design wing
A19: Project 3 : | B19: UI/UX for Club Websites
A20: Project Lead: | B20: Tejas
A21: Project Duration: | B21: Entire Sem
A22: Project Wing: | B22: UI/UX wing
... A32: Project Wing: | B32: Product Design wing
A34: Recurring Budget
A35: Sr. No. | B35: Description of Item | C35: Cost (per unit) | D35: Quantity | E35: Amount | F35: Reference Link
A36: 1 | B36: PLA Filament | C36: 800 | D36: 6 | E36: =C36*D36 -> 4800 | F36: https://robu.in/product/esun-pla-1-75mm-3d-printing-filament-1kg-white/?gad_source=4&gad_campaignid=17419548856&gbraid=0AAAAADvLFWf2SIDUaccUwHlfAeMs4SyYF&gclid=CjwKCAiAj8LLBhAkEiwAJjbY7_Ax0Ms-V39-rIXTAetuf0bjfkTkdPmywgGqwcP6Ya4ZFGptPpkuZxoCngcQAvD_BwE
A37: 2 | B37: ABS Filament | C37: 800 | D37: 3 | E37: =C37*D37 -> 2400 | F37: https://robu.in/product/esun-abs-1-75mm-3d-printing-filament-1kg-black/?gad_source=1&gad_campaignid=17419548856&gbraid=0AAAAADvLFWc3JzN_Wr3jCjxQoIzq7fWr-&gclid=CjwKCAjwxITRBhBYEiwA6mZm7eTCt1IRF-HOmaR16DaCDbQet-uMRKTdGoiybo4LzY7rcv_KqRTU7BoCQV0QAvD_BwE
D38: Total | E38: =SUM(E36:E37) -> 7200
A40: Non-Recurring Budget
A41: Sr. No. | B41: Description of Item | C41: Cost (per unit) | D41: Quantity | E41: Amount | F41: Reference Link
A42: 1 | B42: Graphic Tablets | C42: 6495 | D42: 4 | E42: =C42*D42 -> 25980 | F42: https://amzn.in/d/0fAzV3DA | G42: Justification
D43: Total | E43: =SUM(E42) -> 25980
A44: Parts for Projects
A45: Sr. No. | B45: Description of Item | C45: Cost (per unit) | D45: Quantity | E45: Amount | F45: Reference Link
A46: 1 | B46: CSR8645 Wireless 4.0 Amplifier Board | C46: 1159 | D46: 1 | E46: =C46*D46 -> 1159 | F46: https://robu.in/product/csr8645-wireless-4-0-amplifier-board-5w5w-apt-x-stereo-receiver-amplifier-module/
A47: 2 | B47: ESP32-WROOM-32 38Pin Development Board WiFi+Bluetooth | C47: 399 | D47: 2 | E47: =C47*D47 -> 798 | F47: Product Link
A48: 3 | B48: 40mm 32 Ohm Mylar Headphone Drivers (Pair) | C48: 150 | D48: 2 | E48: =C48*D48 -> 300 | F48: https://www.amazon.in/Electronic-Spices-Woofer-Double-Speaker/dp/B0BN442KJZ/ref=pb_allspark_dp_sims_pao_desktop_session_based_d_sccl_1_2/522-4252313-0357849?pd_rd_w=he2Md&content-id=amzn1.sym.e84a26b2-5470-42e6-b7fa-162e7bb17185&pf_rd_p=e84a26b2-5470-42e6-b7fa-162e7bb17185&pf_rd_r=KHDBEVJ1MS92BKKBQMSP&pd_rd_wg=qkYT8&pd_rd_r=3dc08e33-159d-40df-8b2f-cbe58170ea67&pd_rd_i=B0BN442KJZ&psc=1
A49: 4 | B49: 40mm 3W 4 Ohm Mini External Speaker Drivers | C49: 125 | D49: 4 | E49: =C49*D49 -> 500 | F49: https://www.amazon.in/ERH-India-Bluetooth-Portable-Loudspeaker/dp/B08V1LMMTD
A50: 5 | B50: PAM8403 2x3W Class D Audio Amplifier Board | C50: 40 | D50: 3 | E50: =C50*D50 -> 120 | F50: Product Link
A51: 6 | B51: SmartElex TP4056 Li-ion Battery Charger Module | C51: 100 | D51: 1 | E51: =C51*D51 -> 100 | F51: https://robu.in/product/smartelex-tp4056-li-ion-battery-charger/
A52: 7 | B52: 3.7V 2000mAH 2PIN Connector Lipo Rechargeable Battery Model | C52: 400 | D52: 1 | E52: =C52*D52 -> 400 | F52: https://www.amazon.in/KP-Original-Battery-Rechargeable-KP-603048/dp/B0GM6RKSB4?source=ps-sl-shoppingads-lpcontext&ref_=fplfs&psc=1&smid=A3QQB9C2QXM7ZJ
A53: 8 | B53: A3144 Hall Effect Magnetic Sensor Module | C53: 28 | D53: 5 | E53: =C53*D53 -> 140 | F53: Product Link
A54: 9 | B54: Miscellaneous (Enamelled Wires, Screws, Aux Jacks) | C54: 1000 | D54: 1 | E54: =C54*D54 -> 1000
A55: 10 | B55: 18650 Single Cell Lithium Battery Holder | C55: 65 | D55: 1 | E55: 65 | F55: product link
...

Sheet Astronomy Club
A1: Overview
A2: Type | B2: Amount
A3: Recurring | B3: =E51+C61 -> 45000
A4: Non-Recurring | B4: =E35 -> 61077
A5: Total | B5: =SUM(B3:B4) -> 106077
A7: Projects
A8: Project-i) Star and weather condition tracker website for IIT Dharwad
A9: Project Lead: Rithika Athawade
A10: Project Duration: 3 months
A12: Project-ii) AI used for stacking of images
A13: project lead: Rahul Mudavath
A14: Project Duration: 3 months
A16: Non-Recurring Budget
A17: Sr. No. | B17: Description of Item | C17: Cost (per unit) | D17: Quantity | E17: Amount | F17: Reference Link
A18: 1 | B18: BRESSER Hunter 10x50 BINOCULARS | C18: 5664 | D18: 4 | E18: 22256 | F18: https://www.tejraj.com/product/bresser-hunter-10x50-binoculars
A19: 2 | B19: Solar filter for binocs | C19: 1947 | D19: 4 | E19: 7788 | F19: Solar Filter for Binocular, Solar Filter For 10x50 Binocular, Baader Solar Film
A20: 3 | B20: 12V 7Amp | Rechargeable Power Tank | C20: 6619 | D20: 1 | E20: 6619 | F20: Power Tank | Telescope Power Supply | GoTo Power Supply | Portable Power Supply
A21: 4 | B21: Satellite TV dish | C21: 4000 | D21: 1 | E21: 4000
A22: 5 | B22: 1420 MHz Low noise Amplifier | C22: 5560 | D22: 1 | E22: 5560 | F22: Nooelec Lana - Ultra Low-Noise Amplifier (LNA) Module for RF & Software Defined Radio (SDR) with Enclosure & Accessories. Wideband 20MHz-4000MHz Frequency Capability with Bias Tee & USB Power Options : Amazon.in: Musical Instruments
A23: 6 | B23: 1420 MHz band pass filter | C23: 4000 | D23: 1 | E23: 4000 | F23: 1420 MHz Bandpass Filter – GPIO LABS
A24: 7 | B24: RLT-SDR V4 | C24: 7349 | D24: 1 | E24: 7349 | F24: Buy RTL-SDR Blog V4 R828D RTL2832U 1PPM TCXO SMA Software Defined Radio Dongle only online | Robu.in
A25: 8 | B25: SMA/N Adaptors(pack of 4) | C25: 880 | D25: 1 | E25: 880 | F25: HALMAX SMA Female to N Female RF Adapter, 50 Ohm Coaxial Connector for RF Testing, Antennas, Wireless Communication, WiFi, SDR, Ham Radio & Broadcast Equipment (Pack of 4) : Amazon.in: Computers & Accessories
A26: 9 | B26: Coaxial Cable | C26: 1280 | D26: 1 | E26: 1280 | F26: Rf Lmr 400 N-Male To N -Male Connector Low Loss Coaxial Extension Cable For/3G/4G/5G/Lte/Ads-B/Ham/Gps/Wifi/Rf Radio To Antenna Use signal booster (Not For Tv, Black, 50 Ohm, 32.8 feet,10 meters. : Amazon.in: Electronics
A27: 10 | B27: 1mm Aluminium Sheet | C27: 295 | D27: 1 | E27: 295 | F27: VITSZEE Pure Aluminium Sheet Metal Plate
A28: 11 | B28: Aluminium for waveguide/throat | C28: 300 | D28: 1 | E28: 300
A29: 12 | B29: SMA female bulkhead connector | C29: 150 | D29: 1 | E29: 150
A30: 13 | B30: Copper/brass rod for probe | C30: 100 | D30: 1 | E30: 100
A31: 14 | B31: M3/M4 screws, nuts and washers | C31: 200 | D31: 1 | E31: 200
A32: 15 | B32: Conductive aluminium tape | C32: 100 | D32: 1 | E32: 100
A33: 16 | B33: PVC/nylon mounting piece | C33: 100 | D33: 1 | E33: 100
A34: 17 | B34: Conductive aluminium tape | C34: 100 | D34: 1 | E34: 100
D35: Total | E35: =SUM(E17:E34) -> 61077
A37: Recurring Budget
A39: Events
A41: Event Name: Astronomy talk
A42: Tentative Date and Duration: Odd semester
A44: Event Name: Open stargazing session/event
A45: Tentative Date and Duration: Odd/even sem(possibly in parsec)
A46: Prize Pool: 5000
A47: Sr. No. | B47: Description of Item | C47: Cost (per unit) | D47: Quantity | E47: Amount
...

Sheet Electronics Club
A2: Type | B2: Amount
A3: Recurring | B3: =SUM(E41, E113, E130) -> 111692
A4: Non-Recurring | B4: =E103 -> #NAME?
A5: Total | B5: =SUM(B3:B4) -> #NAME?
A7: Projects
A8: Project-i) RISC-V Microprocessor
A9: Project Lead: Harshvardhan
A10: Project Duration: Aug 2026 - Mar 2027
A12: Project-ii) Communication Protocols
A13: Project Lead: Maanas
A14: Project Duration: Aug 2026 - Dec 2026
A16: Project-iii) Analog Synthesizer
A17: Project Lead: Tanish
A18: Project Duration: Aug 2026 - Mar 2027
A20: Project-iv) Gesture Control Lock & Controlling BLDC motor using FOC
A21: Project Lead: Shrikant
... A29: Recurring Budget
A30: Sr. No. | B30: Description of Item | C30: Cost (per unit) | D30: Quantity | E30: Amount | F30: Reference Link
A31: 1 | B31: Soldering station | C31: 4304 | D31: 1 | E31: =C31*D31 -> 4304 | F31: Solder Station | G31: General Inventory
A32: 2 | B32: Solder Wire | C32: 253 | D32: 5 | E32: =C32*D32 -> 1265 | F32: Solder Wire | G32: General Inventory
A33: 3 | B33: De-Soldering Wire | C33: 42 | D33: 5 | E33: =C33*D33 -> 210 | F33: De-Solder Wick | G33: General Inventory
A34: 4 | B34: 64GB MicroSD | C34: 1132 | D34: 4 | E34: =C34*D34 -> 4528 | F34: SD Card | G34: General Inventory
A35: 5 | B35: eSUN PLA+ 1.75mm 3D Printing Filament 1kg-White | C35: 800 | D35: 2 | E35: =C35*D35 -> 1600 | F35: Printing Filament | G35: General Inventory
A36: 6 | B36: eSUN PLA+ 1.75mm 3D Printing Filament 1kg-Black | C36: 800 | D36: 2 | E36: =C36*D36 -> 1600 | F36: Printing Filament | G36: General Inventory
A37: 7 | B37: Wire Wrap 230m Red | C37: 392 | D37: 1 | E37: =C37*D37 -> 392 | F37: Wire | G37: General Inventory
A38: 8 | B38: Wire Wrap 230m Black | C38: 439 | D38: 1 | E38: =C38*D38 -> 439 | F38: Wire | G38: General Inventory
A39: 9 | B39: Digilent Basys 3 Artix-7 FPGA Trainer Board | C39: 18728 | D39: 2 | E39: =C39*D39 -> 37456 | F39: https://robu.in/product/digilent-basys-3-artix-7-fpga-trainer-board/ | G39: Digital VLSI
A40: 10 | B40: Micro USB-A to Micro-B Cable 100cm Data & Power Cable | C40: 49 | D40: 2 | E40: =C40*D40 -> 98 | F40: https://robu.in/product/micro-usb-a-to-micro-b-cable-120cm/ | G40: Digital VLSI
A41: Total | E41: =SUM(E31:E40) -> 51892
A44: Non-Recurring Budget
A45: Sr. No. | B45: Description of Item | C45: Cost (per unit) | D45: Quantity | E45: Amount | F45: Reference Link
A46: 1 | B46: Bambu P2S 3D Printer | C46: 95000 | D46: 2 | E46: =C46*D46 -> 190000 | F46: robocraze | G46: General Inventory | H46: It would help us build better project prototypes by allowing us to make custom enclosures, mounts, and mechanical parts whenever needed
A47: 2 | B47: Hakko Soldering Tip - Conical (900M-T-1.2D) | C47: 141 | D47: 5 | E47: =C47*D47 -> 705 | F47: Soldering Tip | G47: General Inventory
A48: 3 | B48: Multitec 150B Wire Stripper and Cutter Durable Electronics Tool | C48: 61 | D48: 3 | E48: =C48*D48 -> 183 | F48: Cutter | G48: General Inventory
A49: 4 | B49: Official Arduino Nano A000005 | C49: 1859 | D49: 10 | E49: =C49*D49 -> 18590 | F49: Arduino Nano | G49: General Inventory | H49: Needed for embedded systems discussions, workshops, and demonstrations involving microcontroller programming and interfacing. These were previously borrowed from the Robotics Club for club activities
A50: 5 | B50: Nano Board R3 CH340 chip With USB Mini Cable compatible with Arduino (soldered) | C50: 211.86 | D50: 5 | E50: =C50*D50 -> 1059.3 | F50: Arduino Nano | G50: General Inventory
A51: 6 | B51: Official Arduino Uno Rev3 A000066 | C51: 1799 | D51: 10 | E51: =C51*D51 -> 17990 | F51: Arduino Uno | G51: General Inventory
A52: 7 | B52: Official Arduino Mega 2560 ATmega2560 MCU Rev3 A000067 | C52: 3849 | D52: 5 | E52: =C52*D52 -> 19245 | F52: Arduino Mega | G52: General Inventory
A53: 8 | B53: Official Arduino Nano ESP32-S3 without Headers ABX00092 | C53: 2099 | D53: 5 | E53: =C53*D53 -> 10495 | F53: Arduino Nano ESP32 | G53: General Inventory | H53: Needed for embedded and communication projects involving wireless applications using Wi-Fi and Bluetooth connectivity
A54: 9 | B54: ESP-WROOM-32 WIFI Bluetooth Networking Smart Component Development Board | C54: 415 | D54: 5 | E54: =C54*D54 -> 2075 | F54: ESP32 | G54: General Inventory
...

Sheet SoI26
A1: S.No. | B1: Items | C1: Description | D1: Mentors | E1: Winners | F1: Amount
A2: 1 | B2: Goodies + Merch | C2: Coding Club PS-1 (PathMatrix) | D2: 6 | E2: 9 | F2: =(E2+D2)*400+2100 -> 8100
A3: 2 | B3: Goodies + Merch | C3: Coding Club PS-2 (RealmShift Odyssey) | D3: 3 | E3: 8 | F3: =(E3+D3)*400+2100 -> 6500
A4: 3 | B4: Goodies + Merch | C4: Coding Club PS-3 (eBPF Sentinel) | D4: 2 | E4: 6 | F4: =(E4+D4)*400+2100 -> 5300
A5: 4 | B5: Goodies + Merch | C5: SDS Club PS-1 (GeoSnap) | D5: 5 | E5: 12 | F5: =(E5+D5)*400+2100 -> 8900
A6: 5 | B6: Goodies + Merch | C6: SDS Club PS-2 (PowerCube) | D6: 3 | E6: 12 | F6: =(E6+D6)*400+2100 -> 8100 | H6: =SUM(D2:D19) -> 47
A7: 6 | B7: Merch | C7: AI Club PS-1 (PromptWise) | D7: 1 | E7: 8 | F7: 3600 | H7: =SUM(E2:E19) -> 122
A8: 7 | B8: Merch | C8: AI Club PS-2 (CacheMind) | D8: 1 | E8: 8 | F8: 3600
A9: 8 | B9: Merch | C9: AI Club PS-3 (MediGuide) | D9: 1 | E9: 8 | F9: 3600
A10: 9 | B10: Merch | C10: AI Club PS-4 (PolyLearn) | D10: 1 | E10: 6 | F10: 2800
A11: 10 | B11: Goodies + Merch | C11: Design Club PS-1 (GlyphCraft) | D11: 1 | E11: 3 | F11: =(E11+D11)*400+2100 -> 3700
A12: 11 | B12: Goodies + Merch | C12: Design Club PS-2 (Kigumi Design) | D12: 1 | E12: 3 | F12: =(E12+D12)*400+2100 -> 3700
A13: 12 | B13: Goodies + Merch | C13: Electronics Club PS (BeyondBits) | D13: 4 | E13: 12 | F13: =(E13+D13)*400+2100 -> 8500
A14: 13 | B14: Goodies + Merch | C14: Ingene Club PS (MaterialSnap) | D14: 2 | E14: 6 | F14: =(E14+D14)*400+2100 -> 5300
A15: 14 | B15: Goodies + Merch | C15: Astronomy Club PS (Orbitron) | D15: 2 | E15: 3 | F15: =(E15+D15)*400+2100 -> 4100
A16: 15 | B16: Goodies + Merch | C16: Robotics Club PS-1 (Cartographer) | D16: 3 | E16: 5 | F16: =(E16+D16)*400+2100 -> 5300
A17: 16 | B17: Goodies + Merch | C17: Robotics Club PS-2 (IronGrip) | D17: 4 | E17: 5 | F17: =(E17+D17)*400+2100 -> 5700
A18: 17 | B18: Goodies + Merch | C18: Robotics Club PS-3 (CyberLeg) | D18: 2 | E18: 5 | F18: =(E18+D18)*400+2100 -> 4900
A19: 18 | B19: Goodies + Merch | C19: Finance Club PS (Art of Compounding) | D19: 5 | E19: 3 | F19: =(E19+D19)*400+2100 -> 5300
A20: 19 | B20: Miscellaneous (Certificates, Offline Implementation, etc.) | F20: 3000
A21: Total | F21: =SUM(F2:F20) -> 100000

Sheet InterIIT
A1: Details | B1: No. of Students | C1: Cost for each student | D1: Total
A2: Travelling | B2: 95 | C2: 10000 | D2: =B2*C2 -> 950000
A3: Daily Allowance | B3: 95 | C3: =500*6 -> 3000 | D3: =B3*C3 -> 285000
A4: On-Campus fees | B4: 95 | C4: =2500*1.18 -> 2950 | D4: =B4*C4 -> 280250
A5: Registration costs | B5: 95 | C5: =1000*1.18 -> 1180 | D5: =B5*C5 -> 112100
A6: Contingent Uniforms | B6: 95 | C6: 1500 | D6: =B6*C6 -> 142500
A7: Problem Statements related Expenditure | B7: - | D7: 160000
B8: -
B9: -
A10: Miscellaneous | B10: - | D10: 50000
A11: Grand Total | D11: =SUM(D2:D10) -> 1979850

Sheet PARSEC
A1: =IFERROR(__xludf.DUMMYFUNCTION("IMPORTRANGE(""https://docs.google.com/spreadsheets/d/1O2uayrrspmxXPrRYflfJX4UhsyHFzckYv06zH6GoXG4/edit?gid=401417689#gid=401417689"", ""Overall!A1:C12"")"),"Sr No") -> Sr No | B1: =IFERROR(__xludf.DUMMYFUNCTION("""COMPUTED_VALUE"""),"Description") -> Description | C1: =IFERROR(__xludf.DUMMYFUNCTION("""COMPUTED_VALUE"""),"Amount") -> Amount
A2: =IFERROR(__xludf.DUMMYFUNCTION("""COMPUTED_VALUE"""),1) -> 1 | B2: =IFERROR(__xludf.DUMMYFUNCTION("""COMPUTED_VALUE"""),"Technical Events") -> Technical Events | C2: =IFERROR(__xludf.DUMMYFUNCTION("""COMPUTED_VALUE"""),450000) -> 450000
A3: =IFERROR(__xludf.DUMMYFUNCTION("""COMPUTED_VALUE"""),2) -> 2 | B3: =IFERROR(__xludf.DUMMYFUNCTION("""COMPUTED_VALUE"""),"Decoration + Mascot") -> Decoration + Mascot | C3: =IFERROR(__xludf.DUMMYFUNCTION("""COMPUTED_VALUE"""),265000) -> 265000
A4: =IFERROR(__xludf.DUMMYFUNCTION("""COMPUTED_VALUE"""),3) -> 3 | B4: =IFERROR(__xludf.DUMMYFUNCTION("""COMPUTED_VALUE"""),"Marketing & Outreach Activities") -> Marketing & Outreach Activities | C4: =IFERROR(__xludf.DUMMYFUNCTION("""COMPUTED_VALUE"""),107500) -> 107500
A5: =IFERROR(__xludf.DUMMYFUNCTION("""COMPUTED_VALUE"""),4) -> 4 | B5: =IFERROR(__xludf.DUMMYFUNCTION("""COMPUTED_VALUE"""),"Organising-support team uniform") -> Organising-support team uniform | C5: =IFERROR(__xludf.DUMMYFUNCTION("""COMPUTED_VALUE"""),140000) -> 140000
A6: =IFERROR(__xludf.DUMMYFUNCTION("""COMPUTED_VALUE"""),5) -> 5 | B6: =IFERROR(__xludf.DUMMYFUNCTION("""COMPUTED_VALUE"""),"Subscriptions") -> Subscriptions | C6: =IFERROR(__xludf.DUMMYFUNCTION("""COMPUTED_VALUE"""),46100) -> 46100
A7: =IFERROR(__xludf.DUMMYFUNCTION("""COMPUTED_VALUE"""),6) -> 6 | B7: =IFERROR(__xludf.DUMMYFUNCTION("""COMPUTED_VALUE"""),"Prizes") -> Prizes | C7: =IFERROR(__xludf.DUMMYFUNCTION("""COMPUTED_VALUE"""),250000) -> 250000
A8: =IFERROR(__xludf.DUMMYFUNCTION("""COMPUTED_VALUE"""),7) -> 7 | B8: =IFERROR(__xludf.DUMMYFUNCTION("""COMPUTED_VALUE"""),"Judges & Resource Person") -> Judges & Resource Person | C8: =IFERROR(__xludf.DUMMYFUNCTION("""COMPUTED_VALUE"""),420000) -> 420000
A9: =IFERROR(__xludf.DUMMYFUNCTION("""COMPUTED_VALUE"""),8) -> 8 | B9: =IFERROR(__xludf.DUMMYFUNCTION("""COMPUTED_VALUE"""),"Stage & Sound Setup") -> Stage & Sound Setup | C9: =IFERROR(__xludf.DUMMYFUNCTION("""COMPUTED_VALUE"""),650000) -> 650000
A10: =IFERROR(__xludf.DUMMYFUNCTION("""COMPUTED_VALUE"""),9) -> 9 | B10: =IFERROR(__xludf.DUMMYFUNCTION("""COMPUTED_VALUE"""),"Networking Dinner") -> Networking Dinner | C10: =IFERROR(__xludf.DUMMYFUNCTION("""COMPUTED_VALUE"""),280000) -> 280000
A11: =IFERROR(__xludf.DUMMYFUNCTION("""COMPUTED_VALUE"""),10) -> 10 | B11: =IFERROR(__xludf.DUMMYFUNCTION("""COMPUTED_VALUE"""),"Miscellaneous") -> Miscellaneous | C11: =IFERROR(__xludf.DUMMYFUNCTION("""COMPUTED_VALUE"""),130430) -> 130430
A12: =IFERROR(__xludf.DUMMYFUNCTION("""COMPUTED_VALUE"""),"Total") -> Total | C12: =IFERROR(__xludf.DUMMYFUNCTION("""COMPUTED_VALUE"""),2739030) -> 2739030 | D12: 2000000

Sheet ClubMerch
A1: Club Merchandise
A3: Club Name | B3: Merch Type | C3: No Of Members (Max.) | D3: Cost | E3: Total
A4: Robotics | B4: T-Shirt | C4: 50 | D4: 500 | E4: =C4*D4 -> 25000
A5: Electronics | B5: Hoodie | C5: 50 | D5: 1000 | E5: =C5*D5 -> 50000
A6: SDS | B6: Hoodie | C6: 30 | D6: 1000 | E6: =C6*D6 -> 30000
A7: InGene | B7: T-Shirt | C7: 30 | D7: 500 | E7: =C7*D7 -> 15000
A8: Astronomy | B8: Hoodie | C8: 30 | D8: 1000 | E8: =C8*D8 -> 30000
A9: AI Club | B9: Hoodie | C9: 30 | D9: 1000 | E9: =C9*D9 -> 30000
A10: Coding club | B10: Hoodie | C10: 20 | D10: 1000 | E10: =C10*D10 -> 20000
A11: Coding club | B11: T-Shirt | C11: 65 | D11: 500 | E11: =C11*D11 -> 32500
A12: Design club | B12: Hoodie | C12: 8 | D12: 1000 | E12: =C12*D12 -> 8000
A13: Design club | B13: T-shirt | C13: 30 | D13: 500 | E13: =C13*D13 -> 15000
A14: Insolvent | B14: Hoodie | C14: 4 | D14: 1000 | E14: =C14*D14 -> 4000
A15: Insolvent | B15: T-Shirt | C15: 30 | D15: 500 | E15: =C15*D15 -> 15000
A16: Secretaries | B16: Hoodie+T-shirt | C16: 20 | D16: 1500 | E16: =C16*D16 -> 30000
D17: Total | E17: =SUM(E4:E16) -> 304500
